INFO 2020-04-22 22:12:04,937 basehttp 154 "GET / HTTP/1.1" 200 14708
INFO 2020-04-22 22:12:05,188 basehttp 154 "GET /static/css/PandaBangumi.css HTTP/1.1" 200 3008
INFO 2020-04-22 22:12:05,195 basehttp 154 "GET /static/css/bunlde.css HTTP/1.1" 200 33832
INFO 2020-04-22 22:12:05,208 basehttp 154 "GET /static/css/VOID.css HTTP/1.1" 200 168402
INFO 2020-04-22 22:12:05,210 basehttp 154 "GET /static/css/DoubanBoard.07.css HTTP/1.1" 200 4613
INFO 2020-04-22 22:12:05,213 basehttp 154 "GET /static/css/ExSearch.css HTTP/1.1" 200 6518
INFO 2020-04-22 22:12:05,221 basehttp 154 "GET /static/js/VOID.js HTTP/1.1" 200 14862
INFO 2020-04-22 22:12:05,222 basehttp 154 "GET /static/js/Meting.js HTTP/1.1" 200 3669
INFO 2020-04-22 22:12:05,225 basehttp 154 "GET /static/js/MathJax.js HTTP/1.1" 200 304611
INFO 2020-04-22 22:12:05,226 basehttp 154 "GET /static/js/PandaBangumi.js HTTP/1.1" 200 1975
INFO 2020-04-22 22:12:05,228 basehttp 154 "GET /static/js/DoubanBoard.js HTTP/1.1" 200 7921
INFO 2020-04-22 22:12:05,230 basehttp 154 "GET /static/js/header.js HTTP/1.1" 200 13102
INFO 2020-04-22 22:12:05,232 basehttp 154 "GET /static/js/bundle.js HTTP/1.1" 200 279982
INFO 2020-04-22 22:12:05,236 basehttp 154 "GET /static/js/bundle-header.js HTTP/1.1" 200 158312
INFO 2020-04-22 22:12:05,249 basehttp 154 "GET /static/js/ExSearch.js HTTP/1.1" 200 6813
WARNING 2020-04-22 22:12:05,577 basehttp 154 "GET /static/json/ExSearch.json HTTP/1.1" 404 1678
INFO 2020-04-22 22:12:05,633 basehttp 154 "GET /media/image/index_banner.jpg HTTP/1.1" 200 213520
WARNING 2020-04-22 22:12:05,786 log 228 Not Found: /favicon.ico
WARNING 2020-04-22 22:12:05,786 basehttp 154 "GET /favicon.ico HTTP/1.1" 404 5104
INFO 2020-04-22 22:12:09,498 basehttp 154 "GET /bangumi/?_pjax=%23pjax-container HTTP/1.1" 200 15615
INFO 2020-04-22 22:12:09,528 views 62 获取bangumi_dict.json失败: [Errno 2] No such file or directory: 'F:\\work\\my_lesson\\python\\django_mod\\Django_VOID_Blog/static/json/bangumi_dict.json'
INFO 2020-04-22 22:12:09,529 basehttp 154 "GET /bangumi/json/?from=0 HTTP/1.1" 200 2
INFO 2020-04-22 22:12:09,539 basehttp 154 "GET /media/image/%E8%BF%BD%E7%95%AA.jpg HTTP/1.1" 200 398082
INFO 2020-04-22 22:12:14,696 basehttp 154 "GET /movie/?_pjax=%23pjax-container HTTP/1.1" 200 15835
INFO 2020-04-22 22:12:14,732 basehttp 154 "GET /media/image/%E8%A7%82%E5%BD%B1.jpg HTTP/1.1" 200 152804
INFO 2020-04-22 22:12:16,088 basehttp 154 "GET /bangumi/?_pjax=%23pjax-container HTTP/1.1" 200 15615
INFO 2020-04-22 22:12:16,102 views 62 获取bangumi_dict.json失败: [Errno 2] No such file or directory: 'F:\\work\\my_lesson\\python\\django_mod\\Django_VOID_Blog/static/json/bangumi_dict.json'
INFO 2020-04-22 22:12:16,103 basehttp 154 "GET /bangumi/json/?from=0 HTTP/1.1" 200 2
WARNING 2020-04-22 22:21:59,975 basehttp 154 "GET /static/json/ExSearch.json HTTP/1.1" 404 1678
WARNING 2020-04-22 22:23:56,980 basehttp 154 "GET /static/json/ExSearch.json HTTP/1.1" 404 1678
WARNING 2020-04-22 22:24:06,820 basehttp 154 "GET /static/json/ExSearch.json HTTP/1.1" 404 1678
WARNING 2020-04-22 22:24:06,855 log 228 Not Found: /favicon.ico
WARNING 2020-04-22 22:24:06,856 basehttp 154 "GET /favicon.ico HTTP/1.1" 404 5104
WARNING 2020-04-22 22:24:24,796 basehttp 154 "GET /static/json/ExSearch.json HTTP/1.1" 404 1678
WARNING 2020-04-22 22:24:24,859 basehttp 154 "GET /static/css/fonts/void-icon.eot?64352462 HTTP/1.1" 404 1702
WARNING 2020-04-22 22:24:28,496 basehttp 154 "GET /static/json/ExSearch.json HTTP/1.1" 404 1678
WARNING 2020-04-22 22:24:33,607 basehttp 154 "GET /static/json/ExSearch.json HTTP/1.1" 404 1678
WARNING 2020-04-22 22:25:00,041 basehttp 154 "GET /static/json/ExSearch.json HTTP/1.1" 404 1678
WARNING 2020-04-22 22:25:00,145 log 228 Not Found: /favicon.ico
WARNING 2020-04-22 22:25:00,146 basehttp 154 "GET /favicon.ico HTTP/1.1" 404 5104
WARNING 2020-04-22 22:25:31,528 log 228 Not Found: /favicon.ico
WARNING 2020-04-22 22:25:31,528 basehttp 154 "GET /favicon.ico HTTP/1.1" 404 5104
WARNING 2020-04-22 22:25:32,738 basehttp 154 "GET /static/json/ExSearch.json HTTP/1.1" 404 1678
WARNING 2020-04-22 22:25:32,792 log 228 Not Found: /favicon.ico
WARNING 2020-04-22 22:25:32,792 basehttp 154 "GET /favicon.ico HTTP/1.1" 404 5104
WARNING 2020-04-22 22:25:42,988 basehttp 154 "GET /static/json/ExSearch.json HTTP/1.1" 404 1678
WARNING 2020-04-28 23:45:39,885 basehttp 154 "GET /static/json/ExSearch.json HTTP/1.1" 404 1678
WARNING 2020-04-28 23:45:40,106 log 228 Not Found: /favicon.ico
WARNING 2020-04-28 23:45:40,107 basehttp 154 "GET /favicon.ico HTTP/1.1" 404 5104
WARNING 2020-04-29 00:06:11,813 basehttp 154 "GET /static/json/ExSearch.json HTTP/1.1" 404 1678
WARNING 2020-04-29 00:47:39,075 basehttp 154 "GET /static/json/ExSearch.json HTTP/1.1" 404 1678
WARNING 2020-04-29 00:47:52,564 basehttp 154 "GET /static/json/ExSearch.json HTTP/1.1" 404 1678
WARNING 2020-04-29 00:50:09,082 basehttp 154 "GET /static/json/ExSearch.json HTTP/1.1" 404 1678
WARNING 2020-04-29 00:50:10,196 basehttp 154 "GET /static/json/ExSearch.json HTTP/1.1" 404 1678
WARNING 2020-04-29 00:51:10,747 basehttp 154 "GET /static/json/ExSearch.json HTTP/1.1" 404 1678
WARNING 2020-04-29 00:56:46,844 basehttp 154 "GET /static/json/ExSearch.json HTTP/1.1" 404 1678
WARNING 2020-04-29 00:56:46,889 log 228 Not Found: /favicon.ico
WARNING 2020-04-29 00:56:46,889 basehttp 154 "GET /favicon.ico HTTP/1.1" 404 5104
WARNING 2020-04-29 01:03:33,220 log 228 Not Found: /favicon.ico
WARNING 2020-04-29 01:03:33,220 basehttp 154 "GET /favicon.ico HTTP/1.1" 404 5104
WARNING 2020-04-29 01:03:34,112 basehttp 154 "GET /static/json/ExSearch.json HTTP/1.1" 404 1678
WARNING 2020-04-29 01:03:34,145 log 228 Not Found: /favicon.ico
WARNING 2020-04-29 01:03:34,146 basehttp 154 "GET /favicon.ico HTTP/1.1" 404 5104
WARNING 2020-04-29 01:03:39,238 basehttp 154 "GET /static/json/ExSearch.json HTTP/1.1" 404 1678
WARNING 2020-04-29 01:04:28,120 basehttp 154 "GET /static/json/ExSearch.json HTTP/1.1" 404 1678
WARNING 2020-04-29 01:04:38,670 basehttp 154 "GET /static/json/ExSearch.json HTTP/1.1" 404 1678
WARNING 2020-04-29 23:44:00,909 basehttp 154 "GET /static/json/ExSearch.json HTTP/1.1" 404 1678
WARNING 2020-04-29 23:44:01,139 log 228 Not Found: /favicon.ico
WARNING 2020-04-29 23:44:01,140 basehttp 154 "GET /favicon.ico HTTP/1.1" 404 5104
WARNING 2020-04-29 23:52:40,207 basehttp 154 "GET /static/json/ExSearch.json HTTP/1.1" 404 1678
ERROR 2020-04-29 23:52:42,750 log 228 Internal Server Error: /music/api/
Traceback (most recent call last):
  File "F:\Anaconda\envs\Django_env\lib\site-packages\urllib3\connectionpool.py", line 677, in urlopen
    chunked=chunked,
  File "F:\Anaconda\envs\Django_env\lib\site-packages\urllib3\connectionpool.py", line 381, in _make_request
    self._validate_conn(conn)
  File "F:\Anaconda\envs\Django_env\lib\site-packages\urllib3\connectionpool.py", line 976, in _validate_conn
    conn.connect()
  File "F:\Anaconda\envs\Django_env\lib\site-packages\urllib3\connection.py", line 370, in connect
    ssl_context=context,
  File "F:\Anaconda\envs\Django_env\lib\site-packages\urllib3\util\ssl_.py", line 377, in ssl_wrap_socket
    return context.wrap_socket(sock, server_hostname=server_hostname)
  File "F:\Anaconda\envs\Django_env\lib\ssl.py", line 401, in wrap_socket
    _context=self, _session=session)
  File "F:\Anaconda\envs\Django_env\lib\ssl.py", line 808, in __init__
    self.do_handshake()
  File "F:\Anaconda\envs\Django_env\lib\ssl.py", line 1061, in do_handshake
    self._sslobj.do_handshake()
  File "F:\Anaconda\envs\Django_env\lib\ssl.py", line 683, in do_handshake
    self._sslobj.do_handshake()
ssl.SSLError: [SSL: TLSV1_ALERT_PROTOCOL_VERSION] tlsv1 alert protocol version (_ssl.c:748)

During handling of the above exception, another exception occurred:

Traceback (most recent call last):
  File "F:\Anaconda\envs\Django_env\lib\site-packages\requests\adapters.py", line 449, in send
    timeout=timeout
  File "F:\Anaconda\envs\Django_env\lib\site-packages\urllib3\connectionpool.py", line 725, in urlopen
    method, url, error=e, _pool=self, _stacktrace=sys.exc_info()[2]
  File "F:\Anaconda\envs\Django_env\lib\site-packages\urllib3\util\retry.py", line 439, in increment
    raise MaxRetryError(_pool, url, error or ResponseError(cause))
urllib3.exceptions.MaxRetryError: HTTPSConnectionPool(host='api.i-meto.com', port=443): Max retries exceeded with url: /meting/api?server=netease&type=playlist&id=3032657695&auth=undefined&r=0.07015886147925854 (Caused by SSLError(SSLError(1, '[SSL: TLSV1_ALERT_PROTOCOL_VERSION] tlsv1 alert protocol version (_ssl.c:748)'),))

During handling of the above exception, another exception occurred:

Traceback (most recent call last):
  File "F:\Anaconda\envs\Django_env\lib\site-packages\django\core\handlers\exception.py", line 34, in inner
    response = get_response(request)
  File "F:\Anaconda\envs\Django_env\lib\site-packages\django\core\handlers\base.py", line 126, in _get_response
    response = self.process_exception_by_middleware(e, request)
  File "F:\Anaconda\envs\Django_env\lib\site-packages\django\core\handlers\base.py", line 124, in _get_response
    response = wrapped_callback(request, *callback_args, **callback_kwargs)
  File "F:\Anaconda\envs\Django_env\lib\site-packages\django\views\generic\base.py", line 68, in view
    return self.dispatch(request, *args, **kwargs)
  File "F:\Anaconda\envs\Django_env\lib\site-packages\django\views\generic\base.py", line 88, in dispatch
    return handler(request, *args, **kwargs)
  File "F:\work\my_lesson\python\django_mod\Django_VOID_Blog\apps\music\views.py", line 56, in get
    data = CrawlAPI(server, type, id, auth, r)
  File "F:\work\my_lesson\python\django_mod\Django_VOID_Blog\utils\CrawlMusic.py", line 20, in CrawlAPI
    res = requests.get(url, headers=header)
  File "F:\Anaconda\envs\Django_env\lib\site-packages\requests\api.py", line 76, in get
    return request('get', url, params=params, **kwargs)
  File "F:\Anaconda\envs\Django_env\lib\site-packages\requests\api.py", line 61, in request
    return session.request(method=method, url=url, **kwargs)
  File "F:\Anaconda\envs\Django_env\lib\site-packages\requests\sessions.py", line 530, in request
    resp = self.send(prep, **send_kwargs)
  File "F:\Anaconda\envs\Django_env\lib\site-packages\requests\sessions.py", line 643, in send
    r = adapter.send(request, **kwargs)
  File "F:\Anaconda\envs\Django_env\lib\site-packages\requests\adapters.py", line 514, in send
    raise SSLError(e, request=request)
requests.exceptions.SSLError: HTTPSConnectionPool(host='api.i-meto.com', port=443): Max retries exceeded with url: /meting/api?server=netease&type=playlist&id=3032657695&auth=undefined&r=0.07015886147925854 (Caused by SSLError(SSLError(1, '[SSL: TLSV1_ALERT_PROTOCOL_VERSION] tlsv1 alert protocol version (_ssl.c:748)'),))
ERROR 2020-04-29 23:52:42,758 basehttp 154 "GET /music/api/?server=netease&type=playlist&id=3032657695&auth=undefined&r=0.07015886147925854 HTTP/1.1" 500 184245
WARNING 2020-04-29 23:54:55,182 basehttp 154 "GET /static/json/ExSearch.json HTTP/1.1" 404 1678
ERROR 2020-04-29 23:54:55,772 log 228 Internal Server Error: /music/api/
Traceback (most recent call last):
  File "F:\Anaconda\envs\Django_env\lib\site-packages\urllib3\connectionpool.py", line 677, in urlopen
    chunked=chunked,
  File "F:\Anaconda\envs\Django_env\lib\site-packages\urllib3\connectionpool.py", line 381, in _make_request
    self._validate_conn(conn)
  File "F:\Anaconda\envs\Django_env\lib\site-packages\urllib3\connectionpool.py", line 976, in _validate_conn
    conn.connect()
  File "F:\Anaconda\envs\Django_env\lib\site-packages\urllib3\connection.py", line 370, in connect
    ssl_context=context,
  File "F:\Anaconda\envs\Django_env\lib\site-packages\urllib3\util\ssl_.py", line 377, in ssl_wrap_socket
    return context.wrap_socket(sock, server_hostname=server_hostname)
  File "F:\Anaconda\envs\Django_env\lib\ssl.py", line 401, in wrap_socket
    _context=self, _session=session)
  File "F:\Anaconda\envs\Django_env\lib\ssl.py", line 808, in __init__
    self.do_handshake()
  File "F:\Anaconda\envs\Django_env\lib\ssl.py", line 1061, in do_handshake
    self._sslobj.do_handshake()
  File "F:\Anaconda\envs\Django_env\lib\ssl.py", line 683, in do_handshake
    self._sslobj.do_handshake()
ssl.SSLError: [SSL: TLSV1_ALERT_PROTOCOL_VERSION] tlsv1 alert protocol version (_ssl.c:748)

During handling of the above exception, another exception occurred:

Traceback (most recent call last):
  File "F:\Anaconda\envs\Django_env\lib\site-packages\requests\adapters.py", line 449, in send
    timeout=timeout
  File "F:\Anaconda\envs\Django_env\lib\site-packages\urllib3\connectionpool.py", line 725, in urlopen
    method, url, error=e, _pool=self, _stacktrace=sys.exc_info()[2]
  File "F:\Anaconda\envs\Django_env\lib\site-packages\urllib3\util\retry.py", line 439, in increment
    raise MaxRetryError(_pool, url, error or ResponseError(cause))
urllib3.exceptions.MaxRetryError: HTTPSConnectionPool(host='api.i-meto.com', port=443): Max retries exceeded with url: /meting/api?server=netease&type=playlist&id=3032657695&auth=undefined&r=0.9060706564202543 (Caused by SSLError(SSLError(1, '[SSL: TLSV1_ALERT_PROTOCOL_VERSION] tlsv1 alert protocol version (_ssl.c:748)'),))

During handling of the above exception, another exception occurred:

Traceback (most recent call last):
  File "F:\Anaconda\envs\Django_env\lib\site-packages\django\core\handlers\exception.py", line 34, in inner
    response = get_response(request)
  File "F:\Anaconda\envs\Django_env\lib\site-packages\django\core\handlers\base.py", line 126, in _get_response
    response = self.process_exception_by_middleware(e, request)
  File "F:\Anaconda\envs\Django_env\lib\site-packages\django\core\handlers\base.py", line 124, in _get_response
    response = wrapped_callback(request, *callback_args, **callback_kwargs)
  File "F:\Anaconda\envs\Django_env\lib\site-packages\django\views\generic\base.py", line 68, in view
    return self.dispatch(request, *args, **kwargs)
  File "F:\Anaconda\envs\Django_env\lib\site-packages\django\views\generic\base.py", line 88, in dispatch
    return handler(request, *args, **kwargs)
  File "F:\work\my_lesson\python\django_mod\Django_VOID_Blog\apps\music\views.py", line 56, in get
    data = CrawlAPI(server, type, id, auth, r)
  File "F:\work\my_lesson\python\django_mod\Django_VOID_Blog\utils\CrawlMusic.py", line 20, in CrawlAPI
    res = requests.get(url, headers=header, verify=False)
  File "F:\Anaconda\envs\Django_env\lib\site-packages\requests\api.py", line 76, in get
    return request('get', url, params=params, **kwargs)
  File "F:\Anaconda\envs\Django_env\lib\site-packages\requests\api.py", line 61, in request
    return session.request(method=method, url=url, **kwargs)
  File "F:\Anaconda\envs\Django_env\lib\site-packages\requests\sessions.py", line 530, in request
    resp = self.send(prep, **send_kwargs)
  File "F:\Anaconda\envs\Django_env\lib\site-packages\requests\sessions.py", line 643, in send
    r = adapter.send(request, **kwargs)
  File "F:\Anaconda\envs\Django_env\lib\site-packages\requests\adapters.py", line 514, in send
    raise SSLError(e, request=request)
requests.exceptions.SSLError: HTTPSConnectionPool(host='api.i-meto.com', port=443): Max retries exceeded with url: /meting/api?server=netease&type=playlist&id=3032657695&auth=undefined&r=0.9060706564202543 (Caused by SSLError(SSLError(1, '[SSL: TLSV1_ALERT_PROTOCOL_VERSION] tlsv1 alert protocol version (_ssl.c:748)'),))
ERROR 2020-04-29 23:54:55,783 basehttp 154 "GET /music/api/?server=netease&type=playlist&id=3032657695&auth=undefined&r=0.9060706564202543 HTTP/1.1" 500 184239
WARNING 2020-04-29 23:55:53,896 basehttp 154 "GET /static/json/ExSearch.json HTTP/1.1" 404 1678
ERROR 2020-04-29 23:56:59,432 log 228 Internal Server Error: /music/api/
Traceback (most recent call last):
  File "F:\Anaconda\envs\Django_env\lib\site-packages\urllib3\connectionpool.py", line 677, in urlopen
    chunked=chunked,
  File "F:\Anaconda\envs\Django_env\lib\site-packages\urllib3\connectionpool.py", line 381, in _make_request
    self._validate_conn(conn)
  File "F:\Anaconda\envs\Django_env\lib\site-packages\urllib3\connectionpool.py", line 976, in _validate_conn
    conn.connect()
  File "F:\Anaconda\envs\Django_env\lib\site-packages\urllib3\connection.py", line 370, in connect
    ssl_context=context,
  File "F:\Anaconda\envs\Django_env\lib\site-packages\urllib3\util\ssl_.py", line 377, in ssl_wrap_socket
    return context.wrap_socket(sock, server_hostname=server_hostname)
  File "F:\Anaconda\envs\Django_env\lib\ssl.py", line 401, in wrap_socket
    _context=self, _session=session)
  File "F:\Anaconda\envs\Django_env\lib\ssl.py", line 808, in __init__
    self.do_handshake()
  File "F:\Anaconda\envs\Django_env\lib\ssl.py", line 1061, in do_handshake
    self._sslobj.do_handshake()
  File "F:\Anaconda\envs\Django_env\lib\ssl.py", line 683, in do_handshake
    self._sslobj.do_handshake()
ssl.SSLError: [SSL: TLSV1_ALERT_PROTOCOL_VERSION] tlsv1 alert protocol version (_ssl.c:748)

During handling of the above exception, another exception occurred:

Traceback (most recent call last):
  File "F:\Anaconda\envs\Django_env\lib\site-packages\requests\adapters.py", line 449, in send
    timeout=timeout
  File "F:\Anaconda\envs\Django_env\lib\site-packages\urllib3\connectionpool.py", line 725, in urlopen
    method, url, error=e, _pool=self, _stacktrace=sys.exc_info()[2]
  File "F:\Anaconda\envs\Django_env\lib\site-packages\urllib3\util\retry.py", line 439, in increment
    raise MaxRetryError(_pool, url, error or ResponseError(cause))
urllib3.exceptions.MaxRetryError: HTTPSConnectionPool(host='api.i-meto.com', port=443): Max retries exceeded with url: /meting/api?server=netease&type=playlist&id=3032657695&auth=undefined&r=0.5787781360884661 (Caused by SSLError(SSLError(1, '[SSL: TLSV1_ALERT_PROTOCOL_VERSION] tlsv1 alert protocol version (_ssl.c:748)'),))

During handling of the above exception, another exception occurred:

Traceback (most recent call last):
  File "F:\Anaconda\envs\Django_env\lib\site-packages\django\core\handlers\exception.py", line 34, in inner
    response = get_response(request)
  File "F:\Anaconda\envs\Django_env\lib\site-packages\django\core\handlers\base.py", line 126, in _get_response
    response = self.process_exception_by_middleware(e, request)
  File "F:\Anaconda\envs\Django_env\lib\site-packages\django\core\handlers\base.py", line 124, in _get_response
    response = wrapped_callback(request, *callback_args, **callback_kwargs)
  File "F:\Anaconda\envs\Django_env\lib\site-packages\django\views\generic\base.py", line 68, in view
    return self.dispatch(request, *args, **kwargs)
  File "F:\Anaconda\envs\Django_env\lib\site-packages\django\views\generic\base.py", line 88, in dispatch
    return handler(request, *args, **kwargs)
  File "F:\work\my_lesson\python\django_mod\Django_VOID_Blog\apps\music\views.py", line 56, in get
    data = CrawlAPI(server, type, id, auth, r)
  File "F:\work\my_lesson\python\django_mod\Django_VOID_Blog\utils\CrawlMusic.py", line 20, in CrawlAPI
    res = requests.get(url, headers=header, verify=False)
  File "F:\Anaconda\envs\Django_env\lib\site-packages\requests\api.py", line 76, in get
    return request('get', url, params=params, **kwargs)
  File "F:\Anaconda\envs\Django_env\lib\site-packages\requests\api.py", line 61, in request
    return session.request(method=method, url=url, **kwargs)
  File "F:\Anaconda\envs\Django_env\lib\site-packages\requests\sessions.py", line 530, in request
    resp = self.send(prep, **send_kwargs)
  File "F:\Anaconda\envs\Django_env\lib\site-packages\requests\sessions.py", line 643, in send
    r = adapter.send(request, **kwargs)
  File "F:\Anaconda\envs\Django_env\lib\site-packages\requests\adapters.py", line 514, in send
    raise SSLError(e, request=request)
requests.exceptions.SSLError: HTTPSConnectionPool(host='api.i-meto.com', port=443): Max retries exceeded with url: /meting/api?server=netease&type=playlist&id=3032657695&auth=undefined&r=0.5787781360884661 (Caused by SSLError(SSLError(1, '[SSL: TLSV1_ALERT_PROTOCOL_VERSION] tlsv1 alert protocol version (_ssl.c:748)'),))
ERROR 2020-04-29 23:56:59,442 basehttp 154 "GET /music/api/?server=netease&type=playlist&id=3032657695&auth=undefined&r=0.5787781360884661 HTTP/1.1" 500 186216
WARNING 2020-04-30 00:18:55,381 basehttp 154 "GET /static/json/ExSearch.json HTTP/1.1" 404 1678
WARNING 2020-04-30 00:18:55,593 log 228 Not Found: /favicon.ico
WARNING 2020-04-30 00:18:55,593 basehttp 154 "GET /favicon.ico HTTP/1.1" 404 5278
ERROR 2020-04-30 00:28:58,327 log 228 Internal Server Error: /music/api/
Traceback (most recent call last):
  File "F:\Anaconda\envs\Django_env\lib\site-packages\urllib3\connection.py", line 160, in _new_conn
    (self._dns_host, self.port), self.timeout, **extra_kw
  File "F:\Anaconda\envs\Django_env\lib\site-packages\urllib3\util\connection.py", line 61, in create_connection
    for res in socket.getaddrinfo(host, port, family, socket.SOCK_STREAM):
  File "F:\Anaconda\envs\Django_env\lib\socket.py", line 743, in getaddrinfo
    for res in _socket.getaddrinfo(host, port, family, type, proto, flags):
socket.gaierror: [Errno 11001] getaddrinfo failed

During handling of the above exception, another exception occurred:

Traceback (most recent call last):
  File "F:\Anaconda\envs\Django_env\lib\site-packages\urllib3\connectionpool.py", line 677, in urlopen
    chunked=chunked,
  File "F:\Anaconda\envs\Django_env\lib\site-packages\urllib3\connectionpool.py", line 381, in _make_request
    self._validate_conn(conn)
  File "F:\Anaconda\envs\Django_env\lib\site-packages\urllib3\connectionpool.py", line 976, in _validate_conn
    conn.connect()
  File "F:\Anaconda\envs\Django_env\lib\site-packages\urllib3\connection.py", line 308, in connect
    conn = self._new_conn()
  File "F:\Anaconda\envs\Django_env\lib\site-packages\urllib3\connection.py", line 172, in _new_conn
    self, "Failed to establish a new connection: %s" % e
urllib3.exceptions.NewConnectionError: <urllib3.connection.HTTPSConnection object at 0x000002899BEF9160>: Failed to establish a new connection: [Errno 11001] getaddrinfo failed

During handling of the above exception, another exception occurred:

Traceback (most recent call last):
  File "F:\Anaconda\envs\Django_env\lib\site-packages\requests\adapters.py", line 449, in send
    timeout=timeout
  File "F:\Anaconda\envs\Django_env\lib\site-packages\urllib3\connectionpool.py", line 725, in urlopen
    method, url, error=e, _pool=self, _stacktrace=sys.exc_info()[2]
  File "F:\Anaconda\envs\Django_env\lib\site-packages\urllib3\util\retry.py", line 439, in increment
    raise MaxRetryError(_pool, url, error or ResponseError(cause))
urllib3.exceptions.MaxRetryError: HTTPSConnectionPool(host='meting.api.i-meto.com', port=443): Max retries exceeded with url: /retry/?server=netease&id=28378127 (Caused by NewConnectionError('<urllib3.connection.HTTPSConnection object at 0x000002899BEF9160>: Failed to establish a new connection: [Errno 11001] getaddrinfo failed',))

During handling of the above exception, another exception occurred:

Traceback (most recent call last):
  File "F:\Anaconda\envs\Django_env\lib\site-packages\django\core\handlers\exception.py", line 34, in inner
    response = get_response(request)
  File "F:\Anaconda\envs\Django_env\lib\site-packages\django\core\handlers\base.py", line 126, in _get_response
    response = self.process_exception_by_middleware(e, request)
  File "F:\Anaconda\envs\Django_env\lib\site-packages\django\core\handlers\base.py", line 124, in _get_response
    response = wrapped_callback(request, *callback_args, **callback_kwargs)
  File "F:\Anaconda\envs\Django_env\lib\site-packages\django\views\generic\base.py", line 68, in view
    return self.dispatch(request, *args, **kwargs)
  File "F:\Anaconda\envs\Django_env\lib\site-packages\django\views\generic\base.py", line 88, in dispatch
    return handler(request, *args, **kwargs)
  File "F:\work\my_lesson\python\django_mod\Django_VOID_Blog\apps\music\views.py", line 66, in get
    res = requests.get(api.format(server, type, id, auth, r), headers=header, verify=False)
  File "F:\Anaconda\envs\Django_env\lib\site-packages\requests\api.py", line 76, in get
    return request('get', url, params=params, **kwargs)
  File "F:\Anaconda\envs\Django_env\lib\site-packages\requests\api.py", line 61, in request
    return session.request(method=method, url=url, **kwargs)
  File "F:\Anaconda\envs\Django_env\lib\site-packages\requests\sessions.py", line 530, in request
    resp = self.send(prep, **send_kwargs)
  File "F:\Anaconda\envs\Django_env\lib\site-packages\requests\sessions.py", line 665, in send
    history = [resp for resp in gen] if allow_redirects else []
  File "F:\Anaconda\envs\Django_env\lib\site-packages\requests\sessions.py", line 665, in <listcomp>
    history = [resp for resp in gen] if allow_redirects else []
  File "F:\Anaconda\envs\Django_env\lib\site-packages\requests\sessions.py", line 245, in resolve_redirects
    **adapter_kwargs
  File "F:\Anaconda\envs\Django_env\lib\site-packages\requests\sessions.py", line 643, in send
    r = adapter.send(request, **kwargs)
  File "F:\Anaconda\envs\Django_env\lib\site-packages\requests\adapters.py", line 516, in send
    raise ConnectionError(e, request=request)
requests.exceptions.ConnectionError: HTTPSConnectionPool(host='meting.api.i-meto.com', port=443): Max retries exceeded with url: /retry/?server=netease&id=28378127 (Caused by NewConnectionError('<urllib3.connection.HTTPSConnection object at 0x000002899BEF9160>: Failed to establish a new connection: [Errno 11001] getaddrinfo failed',))
ERROR 2020-04-30 00:28:58,335 basehttp 154 "GET /music/api/?server=netease&type=url&id=28378127&auth=922894ab3efb01e743eb04a9b2aec700b6e5aa7454558de2cbf1b8532f978b8c HTTP/1.1" 500 185521
ERROR 2020-04-30 00:35:44,241 log 228 Internal Server Error: /music/api/
Traceback (most recent call last):
  File "F:\Anaconda\envs\Django_env\lib\site-packages\urllib3\connection.py", line 160, in _new_conn
    (self._dns_host, self.port), self.timeout, **extra_kw
  File "F:\Anaconda\envs\Django_env\lib\site-packages\urllib3\util\connection.py", line 61, in create_connection
    for res in socket.getaddrinfo(host, port, family, socket.SOCK_STREAM):
  File "F:\Anaconda\envs\Django_env\lib\socket.py", line 743, in getaddrinfo
    for res in _socket.getaddrinfo(host, port, family, type, proto, flags):
socket.gaierror: [Errno 11001] getaddrinfo failed

During handling of the above exception, another exception occurred:

Traceback (most recent call last):
  File "F:\Anaconda\envs\Django_env\lib\site-packages\urllib3\connectionpool.py", line 677, in urlopen
    chunked=chunked,
  File "F:\Anaconda\envs\Django_env\lib\site-packages\urllib3\connectionpool.py", line 381, in _make_request
    self._validate_conn(conn)
  File "F:\Anaconda\envs\Django_env\lib\site-packages\urllib3\connectionpool.py", line 976, in _validate_conn
    conn.connect()
  File "F:\Anaconda\envs\Django_env\lib\site-packages\urllib3\connection.py", line 308, in connect
    conn = self._new_conn()
  File "F:\Anaconda\envs\Django_env\lib\site-packages\urllib3\connection.py", line 172, in _new_conn
    self, "Failed to establish a new connection: %s" % e
urllib3.exceptions.NewConnectionError: <urllib3.connection.HTTPSConnection object at 0x000002899BE89D68>: Failed to establish a new connection: [Errno 11001] getaddrinfo failed

During handling of the above exception, another exception occurred:

Traceback (most recent call last):
  File "F:\Anaconda\envs\Django_env\lib\site-packages\requests\adapters.py", line 449, in send
    timeout=timeout
  File "F:\Anaconda\envs\Django_env\lib\site-packages\urllib3\connectionpool.py", line 725, in urlopen
    method, url, error=e, _pool=self, _stacktrace=sys.exc_info()[2]
  File "F:\Anaconda\envs\Django_env\lib\site-packages\urllib3\util\retry.py", line 439, in increment
    raise MaxRetryError(_pool, url, error or ResponseError(cause))
urllib3.exceptions.MaxRetryError: HTTPSConnectionPool(host='meting.api.i-meto.com', port=443): Max retries exceeded with url: /retry/?server=netease&id=28378127 (Caused by NewConnectionError('<urllib3.connection.HTTPSConnection object at 0x000002899BE89D68>: Failed to establish a new connection: [Errno 11001] getaddrinfo failed',))

During handling of the above exception, another exception occurred:

Traceback (most recent call last):
  File "F:\Anaconda\envs\Django_env\lib\site-packages\django\core\handlers\exception.py", line 34, in inner
    response = get_response(request)
  File "F:\Anaconda\envs\Django_env\lib\site-packages\django\core\handlers\base.py", line 126, in _get_response
    response = self.process_exception_by_middleware(e, request)
  File "F:\Anaconda\envs\Django_env\lib\site-packages\django\core\handlers\base.py", line 124, in _get_response
    response = wrapped_callback(request, *callback_args, **callback_kwargs)
  File "F:\Anaconda\envs\Django_env\lib\site-packages\django\views\generic\base.py", line 68, in view
    return self.dispatch(request, *args, **kwargs)
  File "F:\Anaconda\envs\Django_env\lib\site-packages\django\views\generic\base.py", line 88, in dispatch
    return handler(request, *args, **kwargs)
  File "F:\work\my_lesson\python\django_mod\Django_VOID_Blog\apps\music\views.py", line 66, in get
    res = requests.get(api.format(server, type, id, auth, r), headers=header, verify=False)
  File "F:\Anaconda\envs\Django_env\lib\site-packages\requests\api.py", line 76, in get
    return request('get', url, params=params, **kwargs)
  File "F:\Anaconda\envs\Django_env\lib\site-packages\requests\api.py", line 61, in request
    return session.request(method=method, url=url, **kwargs)
  File "F:\Anaconda\envs\Django_env\lib\site-packages\requests\sessions.py", line 530, in request
    resp = self.send(prep, **send_kwargs)
  File "F:\Anaconda\envs\Django_env\lib\site-packages\requests\sessions.py", line 665, in send
    history = [resp for resp in gen] if allow_redirects else []
  File "F:\Anaconda\envs\Django_env\lib\site-packages\requests\sessions.py", line 665, in <listcomp>
    history = [resp for resp in gen] if allow_redirects else []
  File "F:\Anaconda\envs\Django_env\lib\site-packages\requests\sessions.py", line 245, in resolve_redirects
    **adapter_kwargs
  File "F:\Anaconda\envs\Django_env\lib\site-packages\requests\sessions.py", line 643, in send
    r = adapter.send(request, **kwargs)
  File "F:\Anaconda\envs\Django_env\lib\site-packages\requests\adapters.py", line 516, in send
    raise ConnectionError(e, request=request)
requests.exceptions.ConnectionError: HTTPSConnectionPool(host='meting.api.i-meto.com', port=443): Max retries exceeded with url: /retry/?server=netease&id=28378127 (Caused by NewConnectionError('<urllib3.connection.HTTPSConnection object at 0x000002899BE89D68>: Failed to establish a new connection: [Errno 11001] getaddrinfo failed',))
ERROR 2020-04-30 00:35:44,245 basehttp 154 "GET /music/api/?server=netease&type=url&id=28378127&auth=922894ab3efb01e743eb04a9b2aec700b6e5aa7454558de2cbf1b8532f978b8c HTTP/1.1" 500 185467
ERROR 2020-04-30 00:36:02,616 log 228 Internal Server Error: /music/api/
Traceback (most recent call last):
  File "F:\Anaconda\envs\Django_env\lib\site-packages\urllib3\connection.py", line 160, in _new_conn
    (self._dns_host, self.port), self.timeout, **extra_kw
  File "F:\Anaconda\envs\Django_env\lib\site-packages\urllib3\util\connection.py", line 61, in create_connection
    for res in socket.getaddrinfo(host, port, family, socket.SOCK_STREAM):
  File "F:\Anaconda\envs\Django_env\lib\socket.py", line 743, in getaddrinfo
    for res in _socket.getaddrinfo(host, port, family, type, proto, flags):
socket.gaierror: [Errno 11001] getaddrinfo failed

During handling of the above exception, another exception occurred:

Traceback (most recent call last):
  File "F:\Anaconda\envs\Django_env\lib\site-packages\urllib3\connectionpool.py", line 677, in urlopen
    chunked=chunked,
  File "F:\Anaconda\envs\Django_env\lib\site-packages\urllib3\connectionpool.py", line 381, in _make_request
    self._validate_conn(conn)
  File "F:\Anaconda\envs\Django_env\lib\site-packages\urllib3\connectionpool.py", line 976, in _validate_conn
    conn.connect()
  File "F:\Anaconda\envs\Django_env\lib\site-packages\urllib3\connection.py", line 308, in connect
    conn = self._new_conn()
  File "F:\Anaconda\envs\Django_env\lib\site-packages\urllib3\connection.py", line 172, in _new_conn
    self, "Failed to establish a new connection: %s" % e
urllib3.exceptions.NewConnectionError: <urllib3.connection.HTTPSConnection object at 0x000002899CFE9E48>: Failed to establish a new connection: [Errno 11001] getaddrinfo failed

During handling of the above exception, another exception occurred:

Traceback (most recent call last):
  File "F:\Anaconda\envs\Django_env\lib\site-packages\requests\adapters.py", line 449, in send
    timeout=timeout
  File "F:\Anaconda\envs\Django_env\lib\site-packages\urllib3\connectionpool.py", line 725, in urlopen
    method, url, error=e, _pool=self, _stacktrace=sys.exc_info()[2]
  File "F:\Anaconda\envs\Django_env\lib\site-packages\urllib3\util\retry.py", line 439, in increment
    raise MaxRetryError(_pool, url, error or ResponseError(cause))
urllib3.exceptions.MaxRetryError: HTTPSConnectionPool(host='meting.api.i-meto.com', port=443): Max retries exceeded with url: /retry/?server=netease&id=28378127 (Caused by NewConnectionError('<urllib3.connection.HTTPSConnection object at 0x000002899CFE9E48>: Failed to establish a new connection: [Errno 11001] getaddrinfo failed',))

During handling of the above exception, another exception occurred:

Traceback (most recent call last):
  File "F:\Anaconda\envs\Django_env\lib\site-packages\django\core\handlers\exception.py", line 34, in inner
    response = get_response(request)
  File "F:\Anaconda\envs\Django_env\lib\site-packages\django\core\handlers\base.py", line 126, in _get_response
    response = self.process_exception_by_middleware(e, request)
  File "F:\Anaconda\envs\Django_env\lib\site-packages\django\core\handlers\base.py", line 124, in _get_response
    response = wrapped_callback(request, *callback_args, **callback_kwargs)
  File "F:\Anaconda\envs\Django_env\lib\site-packages\django\views\generic\base.py", line 68, in view
    return self.dispatch(request, *args, **kwargs)
  File "F:\Anaconda\envs\Django_env\lib\site-packages\django\views\generic\base.py", line 88, in dispatch
    return handler(request, *args, **kwargs)
  File "F:\work\my_lesson\python\django_mod\Django_VOID_Blog\apps\music\views.py", line 66, in get
    res = requests.get(api.format(server, type, id, auth, r), headers=header, verify=False)
  File "F:\Anaconda\envs\Django_env\lib\site-packages\requests\api.py", line 76, in get
    return request('get', url, params=params, **kwargs)
  File "F:\Anaconda\envs\Django_env\lib\site-packages\requests\api.py", line 61, in request
    return session.request(method=method, url=url, **kwargs)
  File "F:\Anaconda\envs\Django_env\lib\site-packages\requests\sessions.py", line 530, in request
    resp = self.send(prep, **send_kwargs)
  File "F:\Anaconda\envs\Django_env\lib\site-packages\requests\sessions.py", line 665, in send
    history = [resp for resp in gen] if allow_redirects else []
  File "F:\Anaconda\envs\Django_env\lib\site-packages\requests\sessions.py", line 665, in <listcomp>
    history = [resp for resp in gen] if allow_redirects else []
  File "F:\Anaconda\envs\Django_env\lib\site-packages\requests\sessions.py", line 245, in resolve_redirects
    **adapter_kwargs
  File "F:\Anaconda\envs\Django_env\lib\site-packages\requests\sessions.py", line 643, in send
    r = adapter.send(request, **kwargs)
  File "F:\Anaconda\envs\Django_env\lib\site-packages\requests\adapters.py", line 516, in send
    raise ConnectionError(e, request=request)
requests.exceptions.ConnectionError: HTTPSConnectionPool(host='meting.api.i-meto.com', port=443): Max retries exceeded with url: /retry/?server=netease&id=28378127 (Caused by NewConnectionError('<urllib3.connection.HTTPSConnection object at 0x000002899CFE9E48>: Failed to establish a new connection: [Errno 11001] getaddrinfo failed',))
ERROR 2020-04-30 00:36:02,623 basehttp 154 "GET /music/api/?server=netease&type=url&id=28378127&auth=922894ab3efb01e743eb04a9b2aec700b6e5aa7454558de2cbf1b8532f978b8c HTTP/1.1" 500 185469
ERROR 2020-04-30 00:36:13,495 log 228 Internal Server Error: /music/api/
Traceback (most recent call last):
  File "F:\Anaconda\envs\Django_env\lib\site-packages\urllib3\connection.py", line 160, in _new_conn
    (self._dns_host, self.port), self.timeout, **extra_kw
  File "F:\Anaconda\envs\Django_env\lib\site-packages\urllib3\util\connection.py", line 61, in create_connection
    for res in socket.getaddrinfo(host, port, family, socket.SOCK_STREAM):
  File "F:\Anaconda\envs\Django_env\lib\socket.py", line 743, in getaddrinfo
    for res in _socket.getaddrinfo(host, port, family, type, proto, flags):
socket.gaierror: [Errno 11001] getaddrinfo failed

During handling of the above exception, another exception occurred:

Traceback (most recent call last):
  File "F:\Anaconda\envs\Django_env\lib\site-packages\urllib3\connectionpool.py", line 677, in urlopen
    chunked=chunked,
  File "F:\Anaconda\envs\Django_env\lib\site-packages\urllib3\connectionpool.py", line 381, in _make_request
    self._validate_conn(conn)
  File "F:\Anaconda\envs\Django_env\lib\site-packages\urllib3\connectionpool.py", line 976, in _validate_conn
    conn.connect()
  File "F:\Anaconda\envs\Django_env\lib\site-packages\urllib3\connection.py", line 308, in connect
    conn = self._new_conn()
  File "F:\Anaconda\envs\Django_env\lib\site-packages\urllib3\connection.py", line 172, in _new_conn
    self, "Failed to establish a new connection: %s" % e
urllib3.exceptions.NewConnectionError: <urllib3.connection.HTTPSConnection object at 0x000002899CF48B70>: Failed to establish a new connection: [Errno 11001] getaddrinfo failed

During handling of the above exception, another exception occurred:

Traceback (most recent call last):
  File "F:\Anaconda\envs\Django_env\lib\site-packages\requests\adapters.py", line 449, in send
    timeout=timeout
  File "F:\Anaconda\envs\Django_env\lib\site-packages\urllib3\connectionpool.py", line 725, in urlopen
    method, url, error=e, _pool=self, _stacktrace=sys.exc_info()[2]
  File "F:\Anaconda\envs\Django_env\lib\site-packages\urllib3\util\retry.py", line 439, in increment
    raise MaxRetryError(_pool, url, error or ResponseError(cause))
urllib3.exceptions.MaxRetryError: HTTPSConnectionPool(host='meting.api.i-meto.com', port=443): Max retries exceeded with url: /retry/?server=netease&id=28378127 (Caused by NewConnectionError('<urllib3.connection.HTTPSConnection object at 0x000002899CF48B70>: Failed to establish a new connection: [Errno 11001] getaddrinfo failed',))

During handling of the above exception, another exception occurred:

Traceback (most recent call last):
  File "F:\Anaconda\envs\Django_env\lib\site-packages\django\core\handlers\exception.py", line 34, in inner
    response = get_response(request)
  File "F:\Anaconda\envs\Django_env\lib\site-packages\django\core\handlers\base.py", line 126, in _get_response
    response = self.process_exception_by_middleware(e, request)
  File "F:\Anaconda\envs\Django_env\lib\site-packages\django\core\handlers\base.py", line 124, in _get_response
    response = wrapped_callback(request, *callback_args, **callback_kwargs)
  File "F:\Anaconda\envs\Django_env\lib\site-packages\django\views\generic\base.py", line 68, in view
    return self.dispatch(request, *args, **kwargs)
  File "F:\Anaconda\envs\Django_env\lib\site-packages\django\views\generic\base.py", line 88, in dispatch
    return handler(request, *args, **kwargs)
  File "F:\work\my_lesson\python\django_mod\Django_VOID_Blog\apps\music\views.py", line 66, in get
    res = requests.get(api.format(server, type, id, auth, r), headers=header, verify=False)
  File "F:\Anaconda\envs\Django_env\lib\site-packages\requests\api.py", line 76, in get
    return request('get', url, params=params, **kwargs)
  File "F:\Anaconda\envs\Django_env\lib\site-packages\requests\api.py", line 61, in request
    return session.request(method=method, url=url, **kwargs)
  File "F:\Anaconda\envs\Django_env\lib\site-packages\requests\sessions.py", line 530, in request
    resp = self.send(prep, **send_kwargs)
  File "F:\Anaconda\envs\Django_env\lib\site-packages\requests\sessions.py", line 665, in send
    history = [resp for resp in gen] if allow_redirects else []
  File "F:\Anaconda\envs\Django_env\lib\site-packages\requests\sessions.py", line 665, in <listcomp>
    history = [resp for resp in gen] if allow_redirects else []
  File "F:\Anaconda\envs\Django_env\lib\site-packages\requests\sessions.py", line 245, in resolve_redirects
    **adapter_kwargs
  File "F:\Anaconda\envs\Django_env\lib\site-packages\requests\sessions.py", line 643, in send
    r = adapter.send(request, **kwargs)
  File "F:\Anaconda\envs\Django_env\lib\site-packages\requests\adapters.py", line 516, in send
    raise ConnectionError(e, request=request)
requests.exceptions.ConnectionError: HTTPSConnectionPool(host='meting.api.i-meto.com', port=443): Max retries exceeded with url: /retry/?server=netease&id=28378127 (Caused by NewConnectionError('<urllib3.connection.HTTPSConnection object at 0x000002899CF48B70>: Failed to establish a new connection: [Errno 11001] getaddrinfo failed',))
ERROR 2020-04-30 00:36:13,498 basehttp 154 "GET /music/api/?server=netease&type=url&id=28378127&auth=922894ab3efb01e743eb04a9b2aec700b6e5aa7454558de2cbf1b8532f978b8c HTTP/1.1" 500 183950
ERROR 2020-04-30 00:38:05,179 log 228 Internal Server Error: /music/api/
Traceback (most recent call last):
  File "F:\Anaconda\envs\Django_env\lib\site-packages\urllib3\connection.py", line 160, in _new_conn
    (self._dns_host, self.port), self.timeout, **extra_kw
  File "F:\Anaconda\envs\Django_env\lib\site-packages\urllib3\util\connection.py", line 61, in create_connection
    for res in socket.getaddrinfo(host, port, family, socket.SOCK_STREAM):
  File "F:\Anaconda\envs\Django_env\lib\socket.py", line 743, in getaddrinfo
    for res in _socket.getaddrinfo(host, port, family, type, proto, flags):
socket.gaierror: [Errno 11001] getaddrinfo failed

During handling of the above exception, another exception occurred:

Traceback (most recent call last):
  File "F:\Anaconda\envs\Django_env\lib\site-packages\urllib3\connectionpool.py", line 677, in urlopen
    chunked=chunked,
  File "F:\Anaconda\envs\Django_env\lib\site-packages\urllib3\connectionpool.py", line 381, in _make_request
    self._validate_conn(conn)
  File "F:\Anaconda\envs\Django_env\lib\site-packages\urllib3\connectionpool.py", line 976, in _validate_conn
    conn.connect()
  File "F:\Anaconda\envs\Django_env\lib\site-packages\urllib3\connection.py", line 308, in connect
    conn = self._new_conn()
  File "F:\Anaconda\envs\Django_env\lib\site-packages\urllib3\connection.py", line 172, in _new_conn
    self, "Failed to establish a new connection: %s" % e
urllib3.exceptions.NewConnectionError: <urllib3.connection.HTTPSConnection object at 0x000002899CF28828>: Failed to establish a new connection: [Errno 11001] getaddrinfo failed

During handling of the above exception, another exception occurred:

Traceback (most recent call last):
  File "F:\Anaconda\envs\Django_env\lib\site-packages\requests\adapters.py", line 449, in send
    timeout=timeout
  File "F:\Anaconda\envs\Django_env\lib\site-packages\urllib3\connectionpool.py", line 725, in urlopen
    method, url, error=e, _pool=self, _stacktrace=sys.exc_info()[2]
  File "F:\Anaconda\envs\Django_env\lib\site-packages\urllib3\util\retry.py", line 439, in increment
    raise MaxRetryError(_pool, url, error or ResponseError(cause))
urllib3.exceptions.MaxRetryError: HTTPSConnectionPool(host='meting.api.i-meto.com', port=443): Max retries exceeded with url: /retry/?server=netease&id=31421443 (Caused by NewConnectionError('<urllib3.connection.HTTPSConnection object at 0x000002899CF28828>: Failed to establish a new connection: [Errno 11001] getaddrinfo failed',))

During handling of the above exception, another exception occurred:

Traceback (most recent call last):
  File "F:\Anaconda\envs\Django_env\lib\site-packages\django\core\handlers\exception.py", line 34, in inner
    response = get_response(request)
  File "F:\Anaconda\envs\Django_env\lib\site-packages\django\core\handlers\base.py", line 126, in _get_response
    response = self.process_exception_by_middleware(e, request)
  File "F:\Anaconda\envs\Django_env\lib\site-packages\django\core\handlers\base.py", line 124, in _get_response
    response = wrapped_callback(request, *callback_args, **callback_kwargs)
  File "F:\Anaconda\envs\Django_env\lib\site-packages\django\views\generic\base.py", line 68, in view
    return self.dispatch(request, *args, **kwargs)
  File "F:\Anaconda\envs\Django_env\lib\site-packages\django\views\generic\base.py", line 88, in dispatch
    return handler(request, *args, **kwargs)
  File "F:\work\my_lesson\python\django_mod\Django_VOID_Blog\apps\music\views.py", line 66, in get
    res = requests.get(api.format(server, type, id, auth, r), headers=header, verify=False)
  File "F:\Anaconda\envs\Django_env\lib\site-packages\requests\api.py", line 76, in get
    return request('get', url, params=params, **kwargs)
  File "F:\Anaconda\envs\Django_env\lib\site-packages\requests\api.py", line 61, in request
    return session.request(method=method, url=url, **kwargs)
  File "F:\Anaconda\envs\Django_env\lib\site-packages\requests\sessions.py", line 530, in request
    resp = self.send(prep, **send_kwargs)
  File "F:\Anaconda\envs\Django_env\lib\site-packages\requests\sessions.py", line 665, in send
    history = [resp for resp in gen] if allow_redirects else []
  File "F:\Anaconda\envs\Django_env\lib\site-packages\requests\sessions.py", line 665, in <listcomp>
    history = [resp for resp in gen] if allow_redirects else []
  File "F:\Anaconda\envs\Django_env\lib\site-packages\requests\sessions.py", line 245, in resolve_redirects
    **adapter_kwargs
  File "F:\Anaconda\envs\Django_env\lib\site-packages\requests\sessions.py", line 643, in send
    r = adapter.send(request, **kwargs)
  File "F:\Anaconda\envs\Django_env\lib\site-packages\requests\adapters.py", line 516, in send
    raise ConnectionError(e, request=request)
requests.exceptions.ConnectionError: HTTPSConnectionPool(host='meting.api.i-meto.com', port=443): Max retries exceeded with url: /retry/?server=netease&id=31421443 (Caused by NewConnectionError('<urllib3.connection.HTTPSConnection object at 0x000002899CF28828>: Failed to establish a new connection: [Errno 11001] getaddrinfo failed',))
ERROR 2020-04-30 00:38:05,182 basehttp 154 "GET /music/api/?server=netease&type=url&id=31421443&auth=99d251423e9d872c4a54695b6a5409ed076cbb5a94d1140dacdf541904248c5d HTTP/1.1" 500 185523
WARNING 2020-04-30 01:36:08,068 basehttp 154 "GET /static/json/ExSearch.json HTTP/1.1" 404 1678
WARNING 2020-04-30 01:36:08,292 log 228 Not Found: /favicon.ico
WARNING 2020-04-30 01:36:08,293 basehttp 154 "GET /favicon.ico HTTP/1.1" 404 5278
WARNING 2020-04-30 01:37:13,375 basehttp 154 "GET /static/json/ExSearch.json HTTP/1.1" 404 1678
WARNING 2020-04-30 01:38:38,208 basehttp 154 "GET /static/json/ExSearch.json HTTP/1.1" 404 1678
ERROR 2020-04-30 01:38:38,309 basehttp 154 "GET /music/api/?server=netease&type=url&id=430297644&auth=aa3c84e3699269c3aff7cb73773e106cca6af3534149bfd796aba2900db0a1ad HTTP/1.1" 500 59
WARNING 2020-04-30 01:40:41,487 basehttp 154 "GET /static/json/ExSearch.json HTTP/1.1" 404 1678
ERROR 2020-04-30 01:40:47,361 basehttp 154 "GET /music/api/?server=netease&type=url&id=430297644&auth=aa3c84e3699269c3aff7cb73773e106cca6af3534149bfd796aba2900db0a1ad HTTP/1.1" 500 59
WARNING 2020-04-30 01:41:03,488 basehttp 154 "GET /static/json/ExSearch.json HTTP/1.1" 404 1678
WARNING 2020-04-30 01:49:21,706 basehttp 154 "GET /static/json/ExSearch.json HTTP/1.1" 404 1678
WARNING 2020-04-30 01:49:21,848 log 228 Not Found: /favicon.ico
WARNING 2020-04-30 01:49:21,848 basehttp 154 "GET /favicon.ico HTTP/1.1" 404 5278
WARNING 2020-04-30 01:51:20,363 basehttp 154 "GET /static/json/ExSearch.json HTTP/1.1" 404 1678
WARNING 2020-04-30 01:51:33,167 basehttp 154 "GET /static/json/ExSearch.json HTTP/1.1" 404 1678
WARNING 2020-04-30 01:51:40,198 basehttp 154 "GET /static/json/ExSearch.json HTTP/1.1" 404 1678
WARNING 2020-04-30 01:51:40,453 log 228 Not Found: /favicon.ico
WARNING 2020-04-30 01:51:40,453 basehttp 154 "GET /favicon.ico HTTP/1.1" 404 5278
WARNING 2020-04-30 01:52:46,942 basehttp 154 "GET /static/json/ExSearch.json HTTP/1.1" 404 1678
ERROR 2020-04-30 01:52:53,285 basehttp 154 "GET /music/api/?server=netease&type=url&id=430297644&auth=aa3c84e3699269c3aff7cb73773e106cca6af3534149bfd796aba2900db0a1ad HTTP/1.1" 500 59
